[TOC]
# error接口
Go语言引入了一个关于错误处理的标准模式，即error接口，它是Go语言内建的接口类型，该接口的定义如下：

```
type error interface {
    Error() string
}
```

Go语言的标准库代码包errors为用户提供如下方法：

```js
package errors

type errorString struct { 
    text string 
}

func New(text string) error { 
    return &errorString{text} 
}

func (e *errorString) Error() string { 
    return e.text 
}
```


另一个可以生成error类型值的方法是调用fmt包中的Errorf函数：

```js
package fmt
import "errors"

func Errorf(format string, args ...interface{}) error {
    return errors.New(Sprintf(format, args...))
}
```

## error接口的使用


```js
package main

import "fmt"
import "errors"

func main() {
	//var err1 error = fmt.Errorf("%s", "this is normol err")
	err1 := fmt.Errorf("%s", "this is normal err1")
	fmt.Println("err1 = ", err1)  // err1 =  this is normal err1

	err2 := errors.New("this is normal err2")
	fmt.Println("err2 = ", err2) // err2 =  this is normal err2
}
```

## error接口的应用
```js
package main

import "fmt"
import "errors"

func MyDiv(a, b int) (result int, err error) {
	err = nil
	if b == 0 {
		err = errors.New("分母不能为0")
	} else {
		result = a / b
	}

	return
}


func main() {
	result, err := MyDiv(10, 0)
	if err != nil {
		fmt.Println("err = ", err)
	} else {
		fmt.Println("reslut = ", result)
	}
}
```

## error接口应用原理
```js
package main

import "fmt"

/*
uintptr 是一种无符号的整数类型，没有指定具体的bit大小但是足以容纳指针。
uintptr类型只有在底层编程是才需要，特别是Go语言和C语言函数库或操作系统接口相交互的地方。
*/
type stack []uintptr

type errorString struct {
	s string
}

func (e *errorString) Error() string  {
	return e.s
}


// 模仿errors.New()
func New(text string) error {
	return &errorString{text}
}


//只是模拟一个错误
func openFile() (int, error)  {
	// return nil, &errorString{"文件错误，自定义"}
	//return 123, New("文件错误")
	return 123, nil
}


func main() {

	content, errs := openFile()

	if errs != nil {
		fmt.Println("error: ", errs)
	} else {
		fmt.Println(content)
	}

}

```


# panic
在通常情况下，向程序使用方报告错误状态的方式可以是返回一个额外的error类型值。

但是，当遇到不可恢复的错误状态的时候，如数组访问越界、空指针引用等，这些运行时错误会引起painc异常。这时，上述错误处理方式显然就不适合了。

反过来讲，在一般情况下，==我们不应通过调用panic函数来报告普通的错误，而应该只把它作为报告致命错误的一种方式==。当某些==不应该发生的场景发生时==，我们就应该==调用panic==。

一般而言，==当panic异常发生时，程序会中断运行，并立即执行在该goroutine（可以先理解成线程，在中被延迟的函数（defer 机制）==。随后，程序崩溃并输出日志信息。日志信息包括panic value和函数调用的堆栈跟踪信息。

不是所有的panic异常都来自运行时，直接调用内置的panic函数也会引发panic异常；

panic函数接受任何值作为参数。

```
func panic(v interface{})
```

## 显式调用panic函数

```js
package main

import "fmt"

func testa() {
	fmt.Println("aaaaaaaaaaaaaaaaa")
}

func testb() {
	//fmt.Println("bbbbbbbbbbbbbbbbbbbb")
	//显式调用panic函数，导致程序中断
	panic("this is a panic test")
}

func testc() {
	fmt.Println("cccccccccccccccccc")
}

func main() {
	testa()
	testb() // //TestB()发生异常，中断程序
	testc()
}

// aaaaaaaaaaaaaaaaa
// panic: this is a panic test
// 
// goroutine 1 [running]:
// main.testb(...)
// 	E:/gocode/src/gostudydemo/5-异常文本文件处理)/03_显式调用panic函数.go:12
// main.main()
// 	E:/gocode/src/gostudydemo/5-异常文本文件处理)/03_显式调用panic函数.go:21 +0x9d
// 
// Process finished with exit code 2
```

## 数组越界到导致panic
```js
package main

import "fmt"

func testa() {
	fmt.Println("aaaaaaaaaaaaaaaaa")
}

func testb(x int) {
	var a [10]int
	a[x] = 111 //当x为20时候，导致数组越界，产生一个panic，导致程序崩溃
}

func testc() {
	fmt.Println("cccccccccccccccccc")
}

func main() {
	testa()
	testb(20)
	testc()
}

// aaaaaaaaaaaaaaaaa
// panic: runtime error: index out of range [20] with length 10
// 
// goroutine 1 [running]:
// main.testb(...)
// 	E:/gocode/src/gostudydemo/5-异常文本文件处理)/04_数组越界到导致panic.go:11
// main.main()
// 	E:/gocode/src/gostudydemo/5-异常文本文件处理)/04_数组越界到导致panic.go:20 +0x8c
// 
// Process finished with exit code 2
```


# recover (恢复)
运行时panic异常一旦被引发就会导致程序崩溃。这当然不是我们愿意看到的，因为谁也不能保证程序不会发生任何运行时错误。

不过，Go语言为我们提供了专用==于“拦截”运行时panic的内建函数——recover==。

它可以是当前的程序==从运行时panic的状态中恢复并重新获得流程控制权==。


```
func recover() interface{}
```
注意：==recover只有在defer调用的函数中有效==。


如果调用了内置函数recover，并且定义该defer语句的函数发生了panic异常，recover会使程序从panic中恢复，并返回panic value。

导致panic异常的函数不会继续运行，但能正常返回。在未发生panic时调用recover，recover会返回nil。



```js
package main

import "fmt"

func testa() {
	fmt.Println("aaaaaaaaaaaaaaaaa")
}

func testb(x int) {

	//设置recover
	defer func() {
		//recover() //可以打印panic的错误信息
		//fmt.Println(recover())
		
		 // panic value被附加到错误信息中；
	     // 并用err变量接收错误信息，返回给调用者。

		if err := recover(); err != nil { //产生了panic异常
			fmt.Println(err)
		}

	}() //别忘了(), 调用此匿名函数

	var a [10]int
	a[x] = 111 //当x为20时候，导致数组越界，产生一个panic，导致程序崩溃
}

func testc() {
	fmt.Println("cccccccccccccccccc")
}

func main() {
	testa()
	testb(20)
	testc()
}

// aaaaaaaaaaaaaaaaa
// runtime error: index out of range [20] with length 10
// cccccccccccccccccc
```



# 参考
- https://www.flysnow.org/2019/01/01/golang-error-handle-suggestion.html